Traceback (most recent call last):
  File "D:\Perkuliahan\Semester 5\Poyek Sains Data\PSD\venv_py3.11\Lib\site-packages\jupyter_core\utils\__init__.py", line 154, in wrapped
    asyncio.get_running_loop()
RuntimeError: no running event loop

During handling of the above exception, another exception occurred:

Traceback (most recent call last):
  File "D:\Perkuliahan\Semester 5\Poyek Sains Data\PSD\venv_py3.11\Lib\site-packages\jupyter_cache\executors\utils.py", line 58, in single_nb_execution
    executenb(
  File "D:\Perkuliahan\Semester 5\Poyek Sains Data\PSD\venv_py3.11\Lib\site-packages\nbclient\client.py", line 1319, in execute
    return NotebookClient(nb=nb, resources=resources, km=km, **kwargs).execute()
           ^^^^^^^^^^^^^^^^^^^^^^^^^^^^^^^^^^^^^^^^^^^^^^^^^^^^^^^^^^^^^^^^^^^^^
  File "D:\Perkuliahan\Semester 5\Poyek Sains Data\PSD\venv_py3.11\Lib\site-packages\jupyter_core\utils\__init__.py", line 158, in wrapped
    return loop.run_until_complete(inner)
           ^^^^^^^^^^^^^^^^^^^^^^^^^^^^^^
  File "C:\Users\MyBook Z Series\AppData\Local\Python\pythoncore-3.11-64\Lib\asyncio\base_events.py", line 654, in run_until_complete
    return future.result()
           ^^^^^^^^^^^^^^^
  File "D:\Perkuliahan\Semester 5\Poyek Sains Data\PSD\venv_py3.11\Lib\site-packages\nbclient\client.py", line 709, in async_execute
    await self.async_execute_cell(
  File "D:\Perkuliahan\Semester 5\Poyek Sains Data\PSD\venv_py3.11\Lib\site-packages\nbclient\client.py", line 1005, in async_execute_cell
    exec_reply = await self.task_poll_for_reply
                 ^^^^^^^^^^^^^^^^^^^^^^^^^^^^^^
  File "D:\Perkuliahan\Semester 5\Poyek Sains Data\PSD\venv_py3.11\Lib\site-packages\nbclient\client.py", line 806, in _async_poll_for_reply
    error_on_timeout_execute_reply = await self._async_handle_timeout(timeout, cell)
                                     ^^^^^^^^^^^^^^^^^^^^^^^^^^^^^^^^^^^^^^^^^^^^^^^
  File "D:\Perkuliahan\Semester 5\Poyek Sains Data\PSD\venv_py3.11\Lib\site-packages\nbclient\client.py", line 856, in _async_handle_timeout
    raise CellTimeoutError.error_from_timeout_and_cell(
nbclient.exceptions.CellTimeoutError: A cell timed out while it was being executed, after 30 seconds.
The message was: Cell execution timed out.
Here is a preview of the cell contents:
-------------------
['# Bagging dengan SVM', 'bagging_svm = BaggingClassifier(', '    estimator=SVC(random_state=42, max_iter=3000),', '    n_estimators=5,  # jangan terlalu besar karena SVM cukup berat', '    random_state=42']
...
['y_pred_svm = bagging_svm.predict(X_test)', '', 'print("\\n=== Bagging dengan SVM ===")', 'print("Accuracy:", accuracy_score(y_test, y_pred_svm))', 'print(classification_report(y_test, y_pred_svm))']
-------------------

